<?xml version="1.0" ?>
<!-- =================================================================================== -->
<!-- |    This document was autogenerated by xacro from ./install/diff_drive/share/diff_drive/urdf/ddrive.urdf.xacro | -->
<!-- |    EDITING THIS FILE BY HAND IS NOT RECOMMENDED                                 | -->
<!-- =================================================================================== -->
<robot name="robot">
  <gazebo>
    <plugin filename="libignition-gazebo-diff-drive-system.so" name="ignition::gazebo::systems::DiffDrive">
      <odom_publish_frequency>100</odom_publish_frequency>
      <left_joint>L_front_wheel</left_joint>
      <right_joint>R_front_wheel</right_joint>
      <wheel_radius>0.6</wheel_radius>
      <topic>/cmd_vel</topic>
      <odom_topic>/odom</odom_topic>
      <gazebo link="L_front_wheel">
        <mu1>0.2</mu1>
        <mu2>0.2</mu2>
      </gazebo>
      <gazebo link="R_front_wheel">
        <mu1>0.2</mu1>
        <mu2>0.2</mu2>
      </gazebo>
    </plugin>
  </gazebo>
  <material name="blue">
    <color rgba="0 0 1.0 1.0"/>
  </material>
  <material name="red">
    <color rgba="1.0 0 0 1.0"/>
  </material>
  <material name="green">
    <color rgba="0 1.0 0 1.0"/>
  </material>
  <material name="black">
    <color rgba="0.2 0.2 0.2 1.0"/>
  </material>
  <link name="base_link">
    <visual>
      <origin rpy="0 0 0" xyz="0 0 0"/>
      <geometry>
        <box size="1.0 2.0 0.5"/>
      </geometry>
      <material name="blue"/>
    </visual>
    <collision>
      <origin rpy="0 0 0" xyz="0 0 0"/>
      <geometry>
        <box size="1.0 2.0 0.5"/>
      </geometry>
    </collision>
    <inertial>
      <mass value="10"/>
      <inertia ixx="1.0416666666666665" ixy="0.0" ixz="0.0" iyy="4.166666666666666" iyz="0.0" izz="3.5416666666666665"/>
    </inertial>
  </link>
  <link name="L_front_wheel">
    <visual>
      <origin rpy="0 1.5707963267948966 0" xyz="0 0 0"/>
      <geometry>
        <cylinder length="0.15000000000000002" radius="0.6"/>
      </geometry>
      <material name="green"/>
    </visual>
    <collision>
      <origin rpy="0 1.5707963267948966 0" xyz="0 0 0"/>
      <geometry>
        <cylinder length="0.15000000000000002" radius="0.6"/>
      </geometry>
    </collision>
    <inertial>
      <mass value="5"/>
      <inertia ixx="0.459375" ixy="0.0" ixz="0.0" iyy="0.8999999999999999" iyz="0.0" izz="0.459375"/>
    </inertial>
  </link>
  <joint name="base_to_L_front_wheel" type="continuous">
    <parent link="base_link"/>
    <child link="L_front_wheel"/>
    <origin xyz="-0.575 0.8 0"/>
    <axis xyz="1 0 0"/>
  </joint>
  <link name="R_front_wheel">
    <visual>
      <origin rpy="0 1.5707963267948966 0" xyz="0 0 0"/>
      <geometry>
        <cylinder length="0.15000000000000002" radius="0.6"/>
      </geometry>
      <material name="green"/>
    </visual>
    <collision>
      <origin rpy="0 1.5707963267948966 0" xyz="0 0 0"/>
      <geometry>
        <cylinder length="0.15000000000000002" radius="0.6"/>
      </geometry>
    </collision>
    <inertial>
      <mass value="5"/>
      <inertia ixx="0.459375" ixy="0.0" ixz="0.0" iyy="0.8999999999999999" iyz="0.0" izz="0.459375"/>
    </inertial>
  </link>
  <joint name="base_to_R_front_wheel" type="continuous">
    <parent link="base_link"/>
    <child link="R_front_wheel"/>
    <origin xyz="0.575 0.8 0"/>
    <axis xyz="1 0 0"/>
  </joint>
  <link name="casterattach_top_L">
    <visual>
      <origin rpy="0 0 0" xyz="0 0 0"/>
      <geometry>
        <box size="0.05 0.15 0.25"/>
      </geometry>
      <material name="red"/>
    </visual>
    <collision>
      <origin rpy="0 0 0" xyz="0 0 0"/>
      <geometry>
        <box size="0.05 0.15 0.25"/>
      </geometry>
    </collision>
    <inertial>
      <mass value="1"/>
      <inertia ixx="0.005416666666666667" ixy="0.0" ixz="0.0" iyy="0.0020833333333333333" iyz="0.0" izz="0.007083333333333332"/>
    </inertial>
  </link>
  <joint name="base_to_top_L_caster_attachment" type="fixed">
    <parent link="base_link"/>
    <child link="casterattach_top_L"/>
    <origin xyz="-0.07500000000000001 -0.9 0.375"/>
  </joint>
  <link name="casterattach_top_R">
    <visual>
      <origin rpy="0 0 0" xyz="0 0 0"/>
      <geometry>
        <box size="0.05 0.15 0.25"/>
      </geometry>
      <material name="red"/>
    </visual>
    <collision>
      <origin rpy="0 0 0" xyz="0 0 0"/>
      <geometry>
        <box size="0.05 0.15 0.25"/>
      </geometry>
    </collision>
    <inertial>
      <mass value="1"/>
      <inertia ixx="0.005416666666666667" ixy="0.0" ixz="0.0" iyy="0.0020833333333333333" iyz="0.0" izz="0.007083333333333332"/>
    </inertial>
  </link>
  <joint name="base_to_top_R_caster_attachment" type="fixed">
    <parent link="base_link"/>
    <child link="casterattach_top_R"/>
    <origin xyz="0.07500000000000001 -0.9 0.375"/>
  </joint>
  <link name="top_caster_wheel">
    <visual>
      <origin rpy="0 1.5707963267948966  0" xyz="0 0 0"/>
      <geometry>
        <cylinder length="0.1" radius="0.15"/>
      </geometry>
      <material name="black"/>
    </visual>
    <collision>
      <origin rpy="0 1.5707963267948966  0" xyz="0 0 0"/>
      <geometry>
        <cylinder length="0.1" radius="0.15"/>
      </geometry>
    </collision>
    <inertial>
      <mass value="1"/>
      <inertia ixx="0.004375" ixy="0.0" ixz="0.0" iyy="0.005000000000000001" iyz="0.0" izz="0.004375"/>
    </inertial>
  </link>
  <joint name="base_to_top_caster_wheel" type="continuous">
    <parent link="base_link"/>
    <child link="top_caster_wheel"/>
    <origin xyz="0 -0.9 0.44999999999999996"/>
    <axis xyz="1 0 0"/>
  </joint>
  <link name="casterattach_bottom_L">
    <visual>
      <origin rpy="0 0 0" xyz="0 0 0"/>
      <geometry>
        <box size="0.05 0.15 0.25"/>
      </geometry>
      <material name="red"/>
    </visual>
    <collision>
      <origin rpy="0 0 0" xyz="0 0 0"/>
      <geometry>
        <box size="0.05 0.15 0.25"/>
      </geometry>
    </collision>
    <inertial>
      <mass value="1"/>
      <inertia ixx="0.005416666666666667" ixy="0.0" ixz="0.0" iyy="0.0020833333333333333" iyz="0.0" izz="0.007083333333333332"/>
    </inertial>
  </link>
  <joint name="base_to_bottom_L_caster_attachment" type="fixed">
    <parent link="base_link"/>
    <child link="casterattach_bottom_L"/>
    <origin xyz="-0.07500000000000001 -0.9 -0.375"/>
  </joint>
  <link name="casterattach_bottom_R">
    <visual>
      <origin rpy="0 0 0" xyz="0 0 0"/>
      <geometry>
        <box size="0.05 0.15 0.25"/>
      </geometry>
      <material name="red"/>
    </visual>
    <collision>
      <origin rpy="0 0 0" xyz="0 0 0"/>
      <geometry>
        <box size="0.05 0.15 0.25"/>
      </geometry>
    </collision>
    <inertial>
      <mass value="1"/>
      <inertia ixx="0.005416666666666667" ixy="0.0" ixz="0.0" iyy="0.0020833333333333333" iyz="0.0" izz="0.007083333333333332"/>
    </inertial>
  </link>
  <joint name="base_to_bottom_R_caster_attachment" type="fixed">
    <parent link="base_link"/>
    <child link="casterattach_bottom_R"/>
    <origin xyz="0.07500000000000001 -0.9 -0.375"/>
  </joint>
  <link name="bottom_caster_wheel">
    <visual>
      <origin rpy="0 1.5707963267948966  0" xyz="0 0 0"/>
      <geometry>
        <cylinder length="0.1" radius="0.15"/>
      </geometry>
      <material name="black"/>
    </visual>
    <collision>
      <origin rpy="0 1.5707963267948966  0" xyz="0 0 0"/>
      <geometry>
        <cylinder length="0.1" radius="0.15"/>
      </geometry>
    </collision>
    <inertial>
      <mass value="1"/>
      <inertia ixx="0.004375" ixy="0.0" ixz="0.0" iyy="0.005000000000000001" iyz="0.0" izz="0.004375"/>
    </inertial>
  </link>
  <joint name="base_to_bottom_caster_wheel" type="continuous">
    <parent link="base_link"/>
    <child link="bottom_caster_wheel"/>
    <origin xyz="0 -0.9 -0.44999999999999996"/>
    <axis xyz="1 0 0"/>
  </joint>
</robot>
